Workbook

Sheet People

Sheet CyberNetwork
A1: ConnA | B1: ConnB | C1: Type
A2: 1 | B2: 2 | C2: Cyber
A3: 1 | B3: 3 | C3: Cyber
A4: 1 | B4: 4 | C4: Cyber
A5: 1 | B5: 5 | C5: Cyber
A6: 2 | B6: 1 | C6: Cyber
A7: 2 | B7: 5 | C7: Cyber
A8: 3 | B8: 1 | C8: Cyber
A9: 4 | B9: 1 | C9: Cyber
A10: 5 | B10: 1 | C10: Cyber
A11: 5 | B11: 2 | C11: Cyber

Sheet PhysicalNetwork
A1: ConnA | B1: ConnB | C1: Type
A2: 1 | B2: 2 | C2: Physical
A3: 2 | B3: 1 | C3: Physical
A4: 2 | B4: 5 | C4: Physical
A5: 3 | B5: 4 | C5: Physical
A6: 4 | B6: 3 | C6: Physical
A7: 4 | B7: 5 | C7: Physical
A8: 5 | B8: 2 | C8: Physical
A9: 5 | B9: 4 | C9: Physical

Sheet PersonPairs
A1: * Note only top 200 words
A2: Num | B2: Person | C2: Atom1 | D2: Atom2 | F2: Num | G2: Person | H2: Atom1 | I2: Atom2 | K2: Num | L2: Person | M2: Atom1 | N2: Atom2 | P2: Num | Q2: Person | R2: Atom1 | S2: Atom2 | U2: Num | V2: Person | W2: Atom1 | X2: Atom2
A3: 1 | B3: May | C3: {=INDEX('Top200'!$A$1:$A$200,RANDBETWEEN(1,ROWS('Top200'!$A$1:$A$200)),1)} -> fact | D3: {=INDEX('Top200'!$A$1:$A$200,RANDBETWEEN(1,ROWS('Top200'!$A$1:$A$200)),1)} -> your | F3: 2 | G3: Brendan | H3: {=INDEX('Top200'!$A$1:$A$200,RANDBETWEEN(1,ROWS('Top200'!$A$1:$A$200)),1)} -> because | I3: {=INDEX('Top200'!$A$1:$A$200,RANDBETWEEN(1,ROWS('Top200'!$A$1:$A$200)),1)} -> way | K3: 3 | L3: Anne | M3: {=INDEX('Top200'!$A$1:$A$200,RANDBETWEEN(1,ROWS('Top200'!$A$1:$A$200)),1)} -> why | N3: {=INDEX('Top200'!$A$1:$A$200,RANDBETWEEN(1,ROWS('Top200'!$A$1:$A$200)),1)} -> woman | P3: 4 | Q3: Joseph | R3: {=INDEX('Top200'!$A$1:$A$200,RANDBETWEEN(1,ROWS('Top200'!$A$1:$A$200)),1)} -> want | S3: {=INDEX('Top200'!$A$1:$A$200,RANDBETWEEN(1,ROWS('Top200'!$A$1:$A$200)),1)} -> ask | U3: 5 | V3: Martian | W3: {=INDEX('Top200'!$A$1:$A$200,RANDBETWEEN(1,ROWS('Top200'!$A$1:$A$200)),1)} -> know | X3: {=INDEX('Top200'!$A$1:$A$200,RANDBETWEEN(1,ROWS('Top200'!$A$1:$A$200)),1)} -> come
A4: 1 | B4: May | C4: {=INDEX('Top200'!$A$1:$A$200,RANDBETWEEN(1,ROWS('Top200'!$A$1:$A$200)),1)} -> might | D4: {=INDEX('Top200'!$A$1:$A$200,RANDBETWEEN(1,ROWS('Top200'!$A$1:$A$200)),1)} -> could | F4: 2 | G4: Brendan | H4: {=INDEX('Top200'!$A$1:$A$200,RANDBETWEEN(1,ROWS('Top200'!$A$1:$A$200)),1)} -> fact | I4: {=INDEX('Top200'!$A$1:$A$200,RANDBETWEEN(1,ROWS('Top200'!$A$1:$A$200)),1)} -> find | K4: 3 | L4: Anne | M4: {=INDEX('Top200'!$A$1:$A$200,RANDBETWEEN(1,ROWS('Top200'!$A$1:$A$200)),1)} -> then | N4: {=INDEX('Top200'!$A$1:$A$200,RANDBETWEEN(1,ROWS('Top200'!$A$1:$A$200)),1)} -> seem | P4: 4 | Q4: Joseph | R4: {=INDEX('Top200'!$A$1:$A$200,RANDBETWEEN(1,ROWS('Top200'!$A$1:$A$200)),1)} -> family | S4: {=INDEX('Top200'!$A$1:$A$200,RANDBETWEEN(1,ROWS('Top200'!$A$1:$A$200)),1)} -> feel | U4: 5 | V4: Martian | W4: {=INDEX('Top200'!$A$1:$A$200,RANDBETWEEN(1,ROWS('Top200'!$A$1:$A$200)),1)} -> when | X4: {=INDEX('Top200'!$A$1:$A$200,RANDBETWEEN(1,ROWS('Top200'!$A$1:$A$200)),1)} -> they
A5: 1 | B5: May | C5: {=INDEX('Top200'!$A$1:$A$200,RANDBETWEEN(1,ROWS('Top200'!$A$1:$A$200)),1)} -> few | D5: {=INDEX('Top200'!$A$1:$A$200,RANDBETWEEN(1,ROWS('Top200'!$A$1:$A$200)),1)} -> would | F5: 2 | G5: Brendan | H5: {=INDEX('Top200'!$A$1:$A$200,RANDBETWEEN(1,ROWS('Top200'!$A$1:$A$200)),1)} -> the | I5: {=INDEX('Top200'!$A$1:$A$200,RANDBETWEEN(1,ROWS('Top200'!$A$1:$A$200)),1)} -> this | K5: 3 | L5: Anne | M5: {=INDEX('Top200'!$A$1:$A$200,RANDBETWEEN(1,ROWS('Top200'!$A$1:$A$200)),1)} -> book | N5: {=INDEX('Top200'!$A$1:$A$200,RANDBETWEEN(1,ROWS('Top200'!$A$1:$A$200)),1)} -> every | P5: 4 | Q5: Joseph | R5: {=INDEX('Top200'!$A$1:$A$200,RANDBETWEEN(1,ROWS('Top200'!$A$1:$A$200)),1)} -> student | S5: {=INDEX('Top200'!$A$1:$A$200,RANDBETWEEN(1,ROWS('Top200'!$A$1:$A$200)),1)} -> two | U5: 5 | V5: Martian | W5: {=INDEX('Top200'!$A$1:$A$200,RANDBETWEEN(1,ROWS('Top200'!$A$1:$A$200)),1)} -> about | X5: {=INDEX('Top200'!$A$1:$A$200,RANDBETWEEN(1,ROWS('Top200'!$A$1:$A$200)),1)} -> can
A6: 1 | B6: May | C6: {=INDEX('Top200'!$A$1:$A$200,RANDBETWEEN(1,ROWS('Top200'!$A$1:$A$200)),1)} -> American | D6: {=INDEX('Top200'!$A$1:$A$200,RANDBETWEEN(1,ROWS('Top200'!$A$1:$A$200)),1)} -> run | F6: 2 | G6: Brendan | H6: {=INDEX('Top200'!$A$1:$A$200,RANDBETWEEN(1,ROWS('Top200'!$A$1:$A$200)),1)} -> say | I6: {=INDEX('Top200'!$A$1:$A$200,RANDBETWEEN(1,ROWS('Top200'!$A$1:$A$200)),1)} -> during | K6: 3 | L6: Anne | M6: {=INDEX('Top200'!$A$1:$A$200,RANDBETWEEN(1,ROWS('Top200'!$A$1:$A$200)),1)} -> own | N6: {=INDEX('Top200'!$A$1:$A$200,RANDBETWEEN(1,ROWS('Top200'!$A$1:$A$200)),1)} -> play | P6: 4 | Q6: Joseph | R6: {=INDEX('Top200'!$A$1:$A$200,RANDBETWEEN(1,ROWS('Top200'!$A$1:$A$200)),1)} -> with | S6: {=INDEX('Top200'!$A$1:$A$200,RANDBETWEEN(1,ROWS('Top200'!$A$1:$A$200)),1)} -> program | U6: 5 | V6: Martian | W6: {=INDEX('Top200'!$A$1:$A$200,RANDBETWEEN(1,ROWS('Top200'!$A$1:$A$200)),1)} -> hold | X6: {=INDEX('Top200'!$A$1:$A$200,RANDBETWEEN(1,ROWS('Top200'!$A$1:$A$200)),1)} -> month
A7: 1 | B7: May | C7: {=INDEX('Top200'!$A$1:$A$200,RANDBETWEEN(1,ROWS('Top200'!$A$1:$A$200)),1)} -> national | D7: {=INDEX('Top200'!$A$1:$A$200,RANDBETWEEN(1,ROWS('Top200'!$A$1:$A$200)),1)} -> run | F7: 2 | G7: Brendan | H7: {=INDEX('Top200'!$A$1:$A$200,RANDBETWEEN(1,ROWS('Top200'!$A$1:$A$200)),1)} -> other | I7: {=INDEX('Top200'!$A$1:$A$200,RANDBETWEEN(1,ROWS('Top200'!$A$1:$A$200)),1)} -> much | K7: 3 | L7: Anne | M7: {=INDEX('Top200'!$A$1:$A$200,RANDBETWEEN(1,ROWS('Top200'!$A$1:$A$200)),1)} -> think | N7: {=INDEX('Top200'!$A$1:$A$200,RANDBETWEEN(1,ROWS('Top200'!$A$1:$A$200)),1)} -> mean | P7: 4 | Q7: Joseph | R7: {=INDEX('Top200'!$A$1:$A$200,RANDBETWEEN(1,ROWS('Top200'!$A$1:$A$200)),1)} -> many | S7: {=INDEX('Top200'!$A$1:$A$200,RANDBETWEEN(1,ROWS('Top200'!$A$1:$A$200)),1)} -> group | U7: 5 | V7: Martian | W7: {=INDEX('Top200'!$A$1:$A$200,RANDBETWEEN(1,ROWS('Top200'!$A$1:$A$200)),1)} -> most | X7: {=INDEX('Top200'!$A$1:$A$200,RANDBETWEEN(1,ROWS('Top200'!$A$1:$A$200)),1)} -> how
A8: 1 | B8: May | C8: {=INDEX('Top200'!$A$1:$A$200,RANDBETWEEN(1,ROWS('Top200'!$A$1:$A$200)),1)} -> those | D8: {=INDEX('Top200'!$A$1:$A$200,RANDBETWEEN(1,ROWS('Top200'!$A$1:$A$200)),1)} -> through | F8: 2 | G8: Brendan | H8: {=INDEX('Top200'!$A$1:$A$200,RANDBETWEEN(1,ROWS('Top200'!$A$1:$A$200)),1)} -> two | I8: {=INDEX('Top200'!$A$1:$A$200,RANDBETWEEN(1,ROWS('Top200'!$A$1:$A$200)),1)} -> more | K8: 3 | L8: Anne | M8: {=INDEX('Top200'!$A$1:$A$200,RANDBETWEEN(1,ROWS('Top200'!$A$1:$A$200)),1)} -> hand | N8: {=INDEX('Top200'!$A$1:$A$200,RANDBETWEEN(1,ROWS('Top200'!$A$1:$A$200)),1)} -> begin | P8: 4 | Q8: Joseph | R8: {=INDEX('Top200'!$A$1:$A$200,RANDBETWEEN(1,ROWS('Top200'!$A$1:$A$200)),1)} -> mean | S8: {=INDEX('Top200'!$A$1:$A$200,RANDBETWEEN(1,ROWS('Top200'!$A$1:$A$200)),1)} -> call | U8: 5 | V8: Martian | W8: {=INDEX('Top200'!$A$1:$A$200,RANDBETWEEN(1,ROWS('Top200'!$A$1:$A$200)),1)} -> may | X8: {=INDEX('Top200'!$A$1:$A$200,RANDBETWEEN(1,ROWS('Top200'!$A$1:$A$200)),1)} -> start
A9: 1 | B9: May | C9: {=INDEX('Top200'!$A$1:$A$200,RANDBETWEEN(1,ROWS('Top200'!$A$1:$A$200)),1)} -> new | D9: {=INDEX('Top200'!$A$1:$A$200,RANDBETWEEN(1,ROWS('Top200'!$A$1:$A$200)),1)} -> year | F9: 2 | G9: Brendan | H9: {=INDEX('Top200'!$A$1:$A$200,RANDBETWEEN(1,ROWS('Top200'!$A$1:$A$200)),1)} -> good | I9: {=INDEX('Top200'!$A$1:$A$200,RANDBETWEEN(1,ROWS('Top200'!$A$1:$A$200)),1)} -> the | K9: 3 | L9: Anne | M9: {=INDEX('Top200'!$A$1:$A$200,RANDBETWEEN(1,ROWS('Top200'!$A$1:$A$200)),1)} -> country | N9: {=INDEX('Top200'!$A$1:$A$200,RANDBETWEEN(1,ROWS('Top200'!$A$1:$A$200)),1)} -> more | P9: 4 | Q9: Joseph | R9: {=INDEX('Top200'!$A$1:$A$200,RANDBETWEEN(1,ROWS('Top200'!$A$1:$A$200)),1)} -> who | S9: {=INDEX('Top200'!$A$1:$A$200,RANDBETWEEN(1,ROWS('Top200'!$A$1:$A$200)),1)} -> people | U9: 5 | V9: Martian | W9: {=INDEX('Top200'!$A$1:$A$200,RANDBETWEEN(1,ROWS('Top200'!$A$1:$A$200)),1)} -> hold | X9: {=INDEX('Top200'!$A$1:$A$200,RANDBETWEEN(1,ROWS('Top200'!$A$1:$A$200)),1)} -> try
A10: 1 | B10: May | C10: {=INDEX('Top200'!$A$1:$A$200,RANDBETWEEN(1,ROWS('Top200'!$A$1:$A$200)),1)} -> just | D10: {=INDEX('Top200'!$A$1:$A$200,RANDBETWEEN(1,ROWS('Top200'!$A$1:$A$200)),1)} -> Mr | F10: 2 | G10: Brendan | H10: {=INDEX('Top200'!$A$1:$A$200,RANDBETWEEN(1,ROWS('Top200'!$A$1:$A$200)),1)} -> million | I10: {=INDEX('Top200'!$A$1:$A$200,RANDBETWEEN(1,ROWS('Top200'!$A$1:$A$200)),1)} -> want | K10: 3 | L10: Anne | M10: {=INDEX('Top200'!$A$1:$A$200,RANDBETWEEN(1,ROWS('Top200'!$A$1:$A$200)),1)} -> these | N10: {=INDEX('Top200'!$A$1:$A$200,RANDBETWEEN(1,ROWS('Top200'!$A$1:$A$200)),1)} -> back | P10: 4 | Q10: Joseph | R10: {=INDEX('Top200'!$A$1:$A$200,RANDBETWEEN(1,ROWS('Top200'!$A$1:$A$200)),1)} -> study | S10: {=INDEX('Top200'!$A$1:$A$200,RANDBETWEEN(1,ROWS('Top200'!$A$1:$A$200)),1)} -> and | U10: 5 | V10: Martian | W10: {=INDEX('Top200'!$A$1:$A$200,RANDBETWEEN(1,ROWS('Top200'!$A$1:$A$200)),1)} -> they | X10: {=INDEX('Top200'!$A$1:$A$200,RANDBETWEEN(1,ROWS('Top200'!$A$1:$A$200)),1)} -> day
A11: 1 | B11: May | C11: {=INDEX('Top200'!$A$1:$A$200,RANDBETWEEN(1,ROWS('Top200'!$A$1:$A$200)),1)} -> which | D11: {=INDEX('Top200'!$A$1:$A$200,RANDBETWEEN(1,ROWS('Top200'!$A$1:$A$200)),1)} -> how | F11: 2 | G11: Brendan | H11: {=INDEX('Top200'!$A$1:$A$200,RANDBETWEEN(1,ROWS('Top200'!$A$1:$A$200)),1)} -> that | I11: {=INDEX('Top200'!$A$1:$A$200,RANDBETWEEN(1,ROWS('Top200'!$A$1:$A$200)),1)} -> hold | K11: 3 | L11: Anne | M11: {=INDEX('Top200'!$A$1:$A$200,RANDBETWEEN(1,ROWS('Top200'!$A$1:$A$200)),1)} -> live | N11: {=INDEX('Top200'!$A$1:$A$200,RANDBETWEEN(1,ROWS('Top200'!$A$1:$A$200)),1)} -> American | P11: 4 | Q11: Joseph | R11: {=INDEX('Top200'!$A$1:$A$200,RANDBETWEEN(1,ROWS('Top200'!$A$1:$A$200)),1)} -> because | S11: {=INDEX('Top200'!$A$1:$A$200,RANDBETWEEN(1,ROWS('Top200'!$A$1:$A$200)),1)} -> country | U11: 5 | V11: Martian | W11: {=INDEX('Top200'!$A$1:$A$200,RANDBETWEEN(1,ROWS('Top200'!$A$1:$A$200)),1)} -> number | X11: {=INDEX('Top200'!$A$1:$A$200,RANDBETWEEN(1,ROWS('Top200'!$A$1:$A$200)),1)} -> school
A12: 1 | B12: May | C12: {=INDEX('Top200'!$A$1:$A$200,RANDBETWEEN(1,ROWS('Top200'!$A$1:$A$200)),1)} -> run | D12: {=INDEX('Top200'!$A$1:$A$200,RANDBETWEEN(1,ROWS('Top200'!$A$1:$A$200)),1)} -> week | F12: 2 | G12: Brendan | H12: {=INDEX('Top200'!$A$1:$A$200,RANDBETWEEN(1,ROWS('Top200'!$A$1:$A$200)),1)} -> talk | I12: {=INDEX('Top200'!$A$1:$A$200,RANDBETWEEN(1,ROWS('Top200'!$A$1:$A$200)),1)} -> our | K12: 3 | L12: Anne | M12: {=INDEX('Top200'!$A$1:$A$200,RANDBETWEEN(1,ROWS('Top200'!$A$1:$A$200)),1)} -> back | N12: {=INDEX('Top200'!$A$1:$A$200,RANDBETWEEN(1,ROWS('Top200'!$A$1:$A$200)),1)} -> million | P12: 4 | Q12: Joseph | R12: {=INDEX('Top200'!$A$1:$A$200,RANDBETWEEN(1,ROWS('Top200'!$A$1:$A$200)),1)} -> get | S12: {=INDEX('Top200'!$A$1:$A$200,RANDBETWEEN(1,ROWS('Top200'!$A$1:$A$200)),1)} -> study | U12: 5 | V12: Martian | W12: {=INDEX('Top200'!$A$1:$A$200,RANDBETWEEN(1,ROWS('Top200'!$A$1:$A$200)),1)} -> night | X12: {=INDEX('Top200'!$A$1:$A$200,RANDBETWEEN(1,ROWS('Top200'!$A$1:$A$200)),1)} -> may
A13: 1 | B13: May | C13: {=INDEX('Top200'!$A$1:$A$200,RANDBETWEEN(1,ROWS('Top200'!$A$1:$A$200)),1)} -> only | D13: {=INDEX('Top200'!$A$1:$A$200,RANDBETWEEN(1,ROWS('Top200'!$A$1:$A$200)),1)} -> want | F13: 2 | G13: Brendan | H13: {=INDEX('Top200'!$A$1:$A$200,RANDBETWEEN(1,ROWS('Top200'!$A$1:$A$200)),1)} -> must | I13: {=INDEX('Top200'!$A$1:$A$200,RANDBETWEEN(1,ROWS('Top200'!$A$1:$A$200)),1)} -> again | K13: 3 | L13: Anne | M13: {=INDEX('Top200'!$A$1:$A$200,RANDBETWEEN(1,ROWS('Top200'!$A$1:$A$200)),1)} -> never | N13: {=INDEX('Top200'!$A$1:$A$200,RANDBETWEEN(1,ROWS('Top200'!$A$1:$A$200)),1)} -> other | P13: 4 | Q13: Joseph | R13: {=INDEX('Top200'!$A$1:$A$200,RANDBETWEEN(1,ROWS('Top200'!$A$1:$A$200)),1)} -> Mr | S13: {=INDEX('Top200'!$A$1:$A$200,RANDBETWEEN(1,ROWS('Top200'!$A$1:$A$200)),1)} -> few | U13: 5 | V13: Martian | W13: {=INDEX('Top200'!$A$1:$A$200,RANDBETWEEN(1,ROWS('Top200'!$A$1:$A$200)),1)} -> who | X13: {=INDEX('Top200'!$A$1:$A$200,RANDBETWEEN(1,ROWS('Top200'!$A$1:$A$200)),1)} -> for
A14: 1 | B14: May | C14: {=INDEX('Top200'!$A$1:$A$200,RANDBETWEEN(1,ROWS('Top200'!$A$1:$A$200)),1)} -> find | D14: {=INDEX('Top200'!$A$1:$A$200,RANDBETWEEN(1,ROWS('Top200'!$A$1:$A$200)),1)} -> group | F14: 2 | G14: Brendan | H14: {=INDEX('Top200'!$A$1:$A$200,RANDBETWEEN(1,ROWS('Top200'!$A$1:$A$200)),1)} -> some | I14: {=INDEX('Top200'!$A$1:$A$200,RANDBETWEEN(1,ROWS('Top200'!$A$1:$A$200)),1)} -> school | K14: 3 | L14: Anne | M14: {=INDEX('Top200'!$A$1:$A$200,RANDBETWEEN(1,ROWS('Top200'!$A$1:$A$200)),1)} -> when | N14: {=INDEX('Top200'!$A$1:$A$200,RANDBETWEEN(1,ROWS('Top200'!$A$1:$A$200)),1)} -> believe | P14: 4 | Q14: Joseph | R14: {=INDEX('Top200'!$A$1:$A$200,RANDBETWEEN(1,ROWS('Top200'!$A$1:$A$200)),1)} -> they | S14: {=INDEX('Top200'!$A$1:$A$200,RANDBETWEEN(1,ROWS('Top200'!$A$1:$A$200)),1)} -> just | U14: 5 | V14: Martian | W14: {=INDEX('Top200'!$A$1:$A$200,RANDBETWEEN(1,ROWS('Top200'!$A$1:$A$200)),1)} -> look | X14: {=INDEX('Top200'!$A$1:$A$200,RANDBETWEEN(1,ROWS('Top200'!$A$1:$A$200)),1)} -> small
... A32: 1 | B32: May | C32: {=INDEX('Top200'!$A$1:$A$200,RANDBETWEEN(1,ROWS('Top200'!$A$1:$A$200)),1)} -> country | D32: {=INDEX('Top200'!$A$1:$A$200,RANDBETWEEN(1,ROWS('Top200'!$A$1:$A$200)),1)} -> same | F32: 2 | G32: Brendan | H32: {=INDEX('Top200'!$A$1:$A$200,RANDBETWEEN(1,ROWS('Top200'!$A$1:$A$200)),1)} -> today | I32: {=INDEX('Top200'!$A$1:$A$200,RANDBETWEEN(1,ROWS('Top200'!$A$1:$A$200)),1)} -> money | K32: 3 | L32: Anne | M32: {=INDEX('Top200'!$A$1:$A$200,RANDBETWEEN(1,ROWS('Top200'!$A$1:$A$200)),1)} -> country | N32: {=INDEX('Top200'!$A$1:$A$200,RANDBETWEEN(1,ROWS('Top200'!$A$1:$A$200)),1)} -> ask | P32: 4 | Q32: Joseph | R32: {=INDEX('Top200'!$A$1:$A$200,RANDBETWEEN(1,ROWS('Top200'!$A$1:$A$200)),1)} -> state | S32: {=INDEX('Top200'!$A$1:$A$200,RANDBETWEEN(1,ROWS('Top200'!$A$1:$A$200)),1)} -> give | U32: 5 | V32: Martian | W32: {=INDEX('Top200'!$A$1:$A$200,RANDBETWEEN(1,ROWS('Top200'!$A$1:$A$200)),1)} -> week | X32: {=INDEX('Top200'!$A$1:$A$200,RANDBETWEEN(1,ROWS('Top200'!$A$1:$A$200)),1)} -> work
A33: 1 | B33: May | C33: {=INDEX('Top200'!$A$1:$A$200,RANDBETWEEN(1,ROWS('Top200'!$A$1:$A$200)),1)} -> about | D33: {=INDEX('Top200'!$A$1:$A$200,RANDBETWEEN(1,ROWS('Top200'!$A$1:$A$200)),1)} -> bring | F33: 2 | G33: Brendan | H33: {=INDEX('Top200'!$A$1:$A$200,RANDBETWEEN(1,ROWS('Top200'!$A$1:$A$200)),1)} -> begin | I33: {=INDEX('Top200'!$A$1:$A$200,RANDBETWEEN(1,ROWS('Top200'!$A$1:$A$200)),1)} -> when | P33: 4 | Q33: Joseph | R33: {=INDEX('Top200'!$A$1:$A$200,RANDBETWEEN(1,ROWS('Top200'!$A$1:$A$200)),1)} -> part | S33: {=INDEX('Top200'!$A$1:$A$200,RANDBETWEEN(1,ROWS('Top200'!$A$1:$A$200)),1)} -> become | U33: 5 | V33: Martian | W33: {=INDEX('Top200'!$A$1:$A$200,RANDBETWEEN(1,ROWS('Top200'!$A$1:$A$200)),1)} -> student | X33: {=INDEX('Top200'!$A$1:$A$200,RANDBETWEEN(1,ROWS('Top200'!$A$1:$A$200)),1)} -> really
A34: 1 | B34: May | C34: {=INDEX('Top200'!$A$1:$A$200,RANDBETWEEN(1,ROWS('Top200'!$A$1:$A$200)),1)} -> book | D34: {=INDEX('Top200'!$A$1:$A$200,RANDBETWEEN(1,ROWS('Top200'!$A$1:$A$200)),1)} -> national | F34: 2 | G34: Brendan | H34: {=INDEX('Top200'!$A$1:$A$200,RANDBETWEEN(1,ROWS('Top200'!$A$1:$A$200)),1)} -> these | I34: {=INDEX('Top200'!$A$1:$A$200,RANDBETWEEN(1,ROWS('Top200'!$A$1:$A$200)),1)} -> who | P34: 4 | Q34: Joseph | R34: {=INDEX('Top200'!$A$1:$A$200,RANDBETWEEN(1,ROWS('Top200'!$A$1:$A$200)),1)} -> still | S34: {=INDEX('Top200'!$A$1:$A$200,RANDBETWEEN(1,ROWS('Top200'!$A$1:$A$200)),1)} -> different | U34: 5 | V34: Martian | W34: {=INDEX('Top200'!$A$1:$A$200,RANDBETWEEN(1,ROWS('Top200'!$A$1:$A$200)),1)} -> story | X34: {=INDEX('Top200'!$A$1:$A$200,RANDBETWEEN(1,ROWS('Top200'!$A$1:$A$200)),1)} -> let
A35: 1 | B35: May | C35: {=INDEX('Top200'!$A$1:$A$200,RANDBETWEEN(1,ROWS('Top200'!$A$1:$A$200)),1)} -> national | D35: {=INDEX('Top200'!$A$1:$A$200,RANDBETWEEN(1,ROWS('Top200'!$A$1:$A$200)),1)} -> not | F35: 2 | G35: Brendan | H35: {=INDEX('Top200'!$A$1:$A$200,RANDBETWEEN(1,ROWS('Top200'!$A$1:$A$200)),1)} -> as | I35: {=INDEX('Top200'!$A$1:$A$200,RANDBETWEEN(1,ROWS('Top200'!$A$1:$A$200)),1)} -> time | P35: 4 | Q35: Joseph | R35: {=INDEX('Top200'!$A$1:$A$200,RANDBETWEEN(1,ROWS('Top200'!$A$1:$A$200)),1)} -> who | S35: {=INDEX('Top200'!$A$1:$A$200,RANDBETWEEN(1,ROWS('Top200'!$A$1:$A$200)),1)} -> book | U35: 5 | V35: Martian | W35: {=INDEX('Top200'!$A$1:$A$200,RANDBETWEEN(1,ROWS('Top200'!$A$1:$A$200)),1)} -> help | X35: {=INDEX('Top200'!$A$1:$A$200,RANDBETWEEN(1,ROWS('Top200'!$A$1:$A$200)),1)} -> one
A36: 1 | B36: May | C36: {=INDEX('Top200'!$A$1:$A$200,RANDBETWEEN(1,ROWS('Top200'!$A$1:$A$200)),1)} -> only | D36: {=INDEX('Top200'!$A$1:$A$200,RANDBETWEEN(1,ROWS('Top200'!$A$1:$A$200)),1)} -> all | F36: 2 | G36: Brendan | H36: {=INDEX('Top200'!$A$1:$A$200,RANDBETWEEN(1,ROWS('Top200'!$A$1:$A$200)),1)} -> ask | I36: {=INDEX('Top200'!$A$1:$A$200,RANDBETWEEN(1,ROWS('Top200'!$A$1:$A$200)),1)} -> come | P36: 4 | Q36: Joseph | R36: {=INDEX('Top200'!$A$1:$A$200,RANDBETWEEN(1,ROWS('Top200'!$A$1:$A$200)),1)} -> become | S36: {=INDEX('Top200'!$A$1:$A$200,RANDBETWEEN(1,ROWS('Top200'!$A$1:$A$200)),1)} -> fact | U36: 5 | V36: Martian | W36: {=INDEX('Top200'!$A$1:$A$200,RANDBETWEEN(1,ROWS('Top200'!$A$1:$A$200)),1)} -> their | X36: {=INDEX('Top200'!$A$1:$A$200,RANDBETWEEN(1,ROWS('Top200'!$A$1:$A$200)),1)} -> child
A37: 1 | B37: May | C37: {=INDEX('Top200'!$A$1:$A$200,RANDBETWEEN(1,ROWS('Top200'!$A$1:$A$200)),1)} -> million | D37: {=INDEX('Top200'!$A$1:$A$200,RANDBETWEEN(1,ROWS('Top200'!$A$1:$A$200)),1)} -> company | F37: 2 | G37: Brendan | H37: {=INDEX('Top200'!$A$1:$A$200,RANDBETWEEN(1,ROWS('Top200'!$A$1:$A$200)),1)} -> feel | I37: {=INDEX('Top200'!$A$1:$A$200,RANDBETWEEN(1,ROWS('Top200'!$A$1:$A$200)),1)} -> money | P37: 4 | Q37: Joseph | R37: {=INDEX('Top200'!$A$1:$A$200,RANDBETWEEN(1,ROWS('Top200'!$A$1:$A$200)),1)} -> money | S37: {=INDEX('Top200'!$A$1:$A$200,RANDBETWEEN(1,ROWS('Top200'!$A$1:$A$200)),1)} -> place | U37: 5 | V37: Martian | W37: {=INDEX('Top200'!$A$1:$A$200,RANDBETWEEN(1,ROWS('Top200'!$A$1:$A$200)),1)} -> what | X37: {=INDEX('Top200'!$A$1:$A$200,RANDBETWEEN(1,ROWS('Top200'!$A$1:$A$200)),1)} -> today
A38: 1 | B38: May | C38: {=INDEX('Top200'!$A$1:$A$200,RANDBETWEEN(1,ROWS('Top200'!$A$1:$A$200)),1)} -> young | D38: {=INDEX('Top200'!$A$1:$A$200,RANDBETWEEN(1,ROWS('Top200'!$A$1:$A$200)),1)} -> way | F38: 2 | G38: Brendan | H38: {=INDEX('Top200'!$A$1:$A$200,RANDBETWEEN(1,ROWS('Top200'!$A$1:$A$200)),1)} -> get | I38: {=INDEX('Top200'!$A$1:$A$200,RANDBETWEEN(1,ROWS('Top200'!$A$1:$A$200)),1)} -> too | P38: 4 | Q38: Joseph | R38: {=INDEX('Top200'!$A$1:$A$200,RANDBETWEEN(1,ROWS('Top200'!$A$1:$A$200)),1)} -> government | S38: {=INDEX('Top200'!$A$1:$A$200,RANDBETWEEN(1,ROWS('Top200'!$A$1:$A$200)),1)} -> first | U38: 5 | V38: Martian | W38: {=INDEX('Top200'!$A$1:$A$200,RANDBETWEEN(1,ROWS('Top200'!$A$1:$A$200)),1)} -> case | X38: {=INDEX('Top200'!$A$1:$A$200,RANDBETWEEN(1,ROWS('Top200'!$A$1:$A$200)),1)} -> happen
A39: 1 | B39: May | C39: {=INDEX('Top200'!$A$1:$A$200,RANDBETWEEN(1,ROWS('Top200'!$A$1:$A$200)),1)} -> number | D39: {=INDEX('Top200'!$A$1:$A$200,RANDBETWEEN(1,ROWS('Top200'!$A$1:$A$200)),1)} -> help | F39: 2 | G39: Brendan | H39: {=INDEX('Top200'!$A$1:$A$200,RANDBETWEEN(1,ROWS('Top200'!$A$1:$A$200)),1)} -> million | I39: {=INDEX('Top200'!$A$1:$A$200,RANDBETWEEN(1,ROWS('Top200'!$A$1:$A$200)),1)} -> become | P39: 4 | Q39: Joseph | R39: {=INDEX('Top200'!$A$1:$A$200,RANDBETWEEN(1,ROWS('Top200'!$A$1:$A$200)),1)} -> case | S39: {=INDEX('Top200'!$A$1:$A$200,RANDBETWEEN(1,ROWS('Top200'!$A$1:$A$200)),1)} -> right | U39: 5 | V39: Martian | W39: {=INDEX('Top200'!$A$1:$A$200,RANDBETWEEN(1,ROWS('Top200'!$A$1:$A$200)),1)} -> turn | X39: {=INDEX('Top200'!$A$1:$A$200,RANDBETWEEN(1,ROWS('Top200'!$A$1:$A$200)),1)} -> into
A40: 1 | B40: May | C40: {=INDEX('Top200'!$A$1:$A$200,RANDBETWEEN(1,ROWS('Top200'!$A$1:$A$200)),1)} -> hear | D40: {=INDEX('Top200'!$A$1:$A$200,RANDBETWEEN(1,ROWS('Top200'!$A$1:$A$200)),1)} -> state | F40: 2 | G40: Brendan | H40: {=INDEX('Top200'!$A$1:$A$200,RANDBETWEEN(1,ROWS('Top200'!$A$1:$A$200)),1)} -> write | I40: {=INDEX('Top200'!$A$1:$A$200,RANDBETWEEN(1,ROWS('Top200'!$A$1:$A$200)),1)} -> different | P40: 4 | Q40: Joseph | R40: {=INDEX('Top200'!$A$1:$A$200,RANDBETWEEN(1,ROWS('Top200'!$A$1:$A$200)),1)} -> with | S40: {=INDEX('Top200'!$A$1:$A$200,RANDBETWEEN(1,ROWS('Top200'!$A$1:$A$200)),1)} -> too | U40: 5 | V40: Martian | W40: {=INDEX('Top200'!$A$1:$A$200,RANDBETWEEN(1,ROWS('Top200'!$A$1:$A$200)),1)} -> way | X40: {=INDEX('Top200'!$A$1:$A$200,RANDBETWEEN(1,ROWS('Top200'!$A$1:$A$200)),1)} -> country
A41: 1 | B41: May | C41: {=INDEX('Top200'!$A$1:$A$200,RANDBETWEEN(1,ROWS('Top200'!$A$1:$A$200)),1)} -> other | D41: {=INDEX('Top200'!$A$1:$A$200,RANDBETWEEN(1,ROWS('Top200'!$A$1:$A$200)),1)} -> people | F41: 2 | G41: Brendan | H41: {=INDEX('Top200'!$A$1:$A$200,RANDBETWEEN(1,ROWS('Top200'!$A$1:$A$200)),1)} -> believe | I41: {=INDEX('Top200'!$A$1:$A$200,RANDBETWEEN(1,ROWS('Top200'!$A$1:$A$200)),1)} -> will | P41: 4 | Q41: Joseph | R41: {=INDEX('Top200'!$A$1:$A$200,RANDBETWEEN(1,ROWS('Top200'!$A$1:$A$200)),1)} -> find | S41: {=INDEX('Top200'!$A$1:$A$200,RANDBETWEEN(1,ROWS('Top200'!$A$1:$A$200)),1)} -> same | U41: 5 | V41: Martian | W41: {=INDEX('Top200'!$A$1:$A$200,RANDBETWEEN(1,ROWS('Top200'!$A$1:$A$200)),1)} -> let | X41: {=INDEX('Top200'!$A$1:$A$200,RANDBETWEEN(1,ROWS('Top200'!$A$1:$A$200)),1)} -> turn
A42: 1 | B42: May | C42: {=INDEX('Top200'!$A$1:$A$200,RANDBETWEEN(1,ROWS('Top200'!$A$1:$A$200)),1)} -> before | D42: {=INDEX('Top200'!$A$1:$A$200,RANDBETWEEN(1,ROWS('Top200'!$A$1:$A$200)),1)} -> too | F42: 2 | G42: Brendan | H42: {=INDEX('Top200'!$A$1:$A$200,RANDBETWEEN(1,ROWS('Top200'!$A$1:$A$200)),1)} -> write | I42: {=INDEX('Top200'!$A$1:$A$200,RANDBETWEEN(1,ROWS('Top200'!$A$1:$A$200)),1)} -> all | U42: 5 | V42: Martian | W42: {=INDEX('Top200'!$A$1:$A$200,RANDBETWEEN(1,ROWS('Top200'!$A$1:$A$200)),1)} -> run | X42: {=INDEX('Top200'!$A$1:$A$200,RANDBETWEEN(1,ROWS('Top200'!$A$1:$A$200)),1)} -> next
A43: 1 | B43: May | C43: {=INDEX('Top200'!$A$1:$A$200,RANDBETWEEN(1,ROWS('Top200'!$A$1:$A$200)),1)} -> any | D43: {=INDEX('Top200'!$A$1:$A$200,RANDBETWEEN(1,ROWS('Top200'!$A$1:$A$200)),1)} -> same | F43: 2 | G43: Brendan | H43: {=INDEX('Top200'!$A$1:$A$200,RANDBETWEEN(1,ROWS('Top200'!$A$1:$A$200)),1)} -> start | I43: {=INDEX('Top200'!$A$1:$A$200,RANDBETWEEN(1,ROWS('Top200'!$A$1:$A$200)),1)} -> again
A44: 1 | B44: May | C44: {=INDEX('Top200'!$A$1:$A$200,RANDBETWEEN(1,ROWS('Top200'!$A$1:$A$200)),1)} -> they | D44: {=INDEX('Top200'!$A$1:$A$200,RANDBETWEEN(1,ROWS('Top200'!$A$1:$A$200)),1)} -> without | F44: 2 | G44: Brendan | H44: {=INDEX('Top200'!$A$1:$A$200,RANDBETWEEN(1,ROWS('Top200'!$A$1:$A$200)),1)} -> then | I44: {=INDEX('Top200'!$A$1:$A$200,RANDBETWEEN(1,ROWS('Top200'!$A$1:$A$200)),1)} -> still
A45: 1 | B45: May | C45: {=INDEX('Top200'!$A$1:$A$200,RANDBETWEEN(1,ROWS('Top200'!$A$1:$A$200)),1)} -> something | D45: {=INDEX('Top200'!$A$1:$A$200,RANDBETWEEN(1,ROWS('Top200'!$A$1:$A$200)),1)} -> over | F45: 2 | G45: Brendan | H45: {=INDEX('Top200'!$A$1:$A$200,RANDBETWEEN(1,ROWS('Top200'!$A$1:$A$200)),1)} -> her | I45: {=INDEX('Top200'!$A$1:$A$200,RANDBETWEEN(1,ROWS('Top200'!$A$1:$A$200)),1)} -> last
A46: 1 | B46: May | C46: {=INDEX('Top200'!$A$1:$A$200,RANDBETWEEN(1,ROWS('Top200'!$A$1:$A$200)),1)} -> how | D46: {=INDEX('Top200'!$A$1:$A$200,RANDBETWEEN(1,ROWS('Top200'!$A$1:$A$200)),1)} -> mother | F46: 2 | G46: Brendan | H46: {=INDEX('Top200'!$A$1:$A$200,RANDBETWEEN(1,ROWS('Top200'!$A$1:$A$200)),1)} -> these | I46: {=INDEX('Top200'!$A$1:$A$200,RANDBETWEEN(1,ROWS('Top200'!$A$1:$A$200)),1)} -> same
A47: 1 | B47: May | C47: {=INDEX('Top200'!$A$1:$A$200,RANDBETWEEN(1,ROWS('Top200'!$A$1:$A$200)),1)} -> for | D47: {=INDEX('Top200'!$A$1:$A$200,RANDBETWEEN(1,ROWS('Top200'!$A$1:$A$200)),1)} -> really | F47: 2 | G47: Brendan | H47: {=INDEX('Top200'!$A$1:$A$200,RANDBETWEEN(1,ROWS('Top200'!$A$1:$A$200)),1)} -> leave | I47: {=INDEX('Top200'!$A$1:$A$200,RANDBETWEEN(1,ROWS('Top200'!$A$1:$A$200)),1)} -> there
A48: 1 | B48: May | C48: {=INDEX('Top200'!$A$1:$A$200,RANDBETWEEN(1,ROWS('Top200'!$A$1:$A$200)),1)} -> may | D48: {=INDEX('Top200'!$A$1:$A$200,RANDBETWEEN(1,ROWS('Top200'!$A$1:$A$200)),1)} -> even | F48: 2 | G48: Brendan | H48: {=INDEX('Top200'!$A$1:$A$200,RANDBETWEEN(1,ROWS('Top200'!$A$1:$A$200)),1)} -> time | I48: {=INDEX('Top200'!$A$1:$A$200,RANDBETWEEN(1,ROWS('Top200'!$A$1:$A$200)),1)} -> happen
A49: 1 | B49: May | C49: {=INDEX('Top200'!$A$1:$A$200,RANDBETWEEN(1,ROWS('Top200'!$A$1:$A$200)),1)} -> all | D49: {=INDEX('Top200'!$A$1:$A$200,RANDBETWEEN(1,ROWS('Top200'!$A$1:$A$200)),1)} -> like | F49: 2 | G49: Brendan | H49: {=INDEX('Top200'!$A$1:$A$200,RANDBETWEEN(1,ROWS('Top200'!$A$1:$A$200)),1)} -> look | I49: {=INDEX('Top200'!$A$1:$A$200,RANDBETWEEN(1,ROWS('Top200'!$A$1:$A$200)),1)} -> American
A50: 1 | B50: May | C50: {=INDEX('Top200'!$A$1:$A$200,RANDBETWEEN(1,ROWS('Top200'!$A$1:$A$200)),1)} -> well | D50: {=INDEX('Top200'!$A$1:$A$200,RANDBETWEEN(1,ROWS('Top200'!$A$1:$A$200)),1)} -> under | F50: 2 | G50: Brendan | H50: {=INDEX('Top200'!$A$1:$A$200,RANDBETWEEN(1,ROWS('Top200'!$A$1:$A$200)),1)} -> say | I50: {=INDEX('Top200'!$A$1:$A$200,RANDBETWEEN(1,ROWS('Top200'!$A$1:$A$200)),1)} -> through
A51: 1 | B51: May | C51: {=INDEX('Top200'!$A$1:$A$200,RANDBETWEEN(1,ROWS('Top200'!$A$1:$A$200)),1)} -> these | D51: {=INDEX('Top200'!$A$1:$A$200,RANDBETWEEN(1,ROWS('Top200'!$A$1:$A$200)),1)} -> such | F51: 2 | G51: Brendan | H51: {=INDEX('Top200'!$A$1:$A$200,RANDBETWEEN(1,ROWS('Top200'!$A$1:$A$200)),1)} -> move | I51: {=INDEX('Top200'!$A$1:$A$200,RANDBETWEEN(1,ROWS('Top200'!$A$1:$A$200)),1)} -> find
A52: 1 | B52: May | C52: {=INDEX('Top200'!$A$1:$A$200,RANDBETWEEN(1,ROWS('Top200'!$A$1:$A$200)),1)} -> keep | D52: {=INDEX('Top200'!$A$1:$A$200,RANDBETWEEN(1,ROWS('Top200'!$A$1:$A$200)),1)} -> become
A53: 1 | B53: May | C53: {=INDEX('Top200'!$A$1:$A$200,RANDBETWEEN(1,ROWS('Top200'!$A$1:$A$200)),1)} -> again | D53: {=INDEX('Top200'!$A$1:$A$200,RANDBETWEEN(1,ROWS('Top200'!$A$1:$A$200)),1)} -> help
A54: 1 | B54: May | C54: {=INDEX('Top200'!$A$1:$A$200,RANDBETWEEN(1,ROWS('Top200'!$A$1:$A$200)),1)} -> woman | D54: {=INDEX('Top200'!$A$1:$A$200,RANDBETWEEN(1,ROWS('Top200'!$A$1:$A$200)),1)} -> they
A55: 1 | B55: May | C55: {=INDEX('Top200'!$A$1:$A$200,RANDBETWEEN(1,ROWS('Top200'!$A$1:$A$200)),1)} -> even | D55: {=INDEX('Top200'!$A$1:$A$200,RANDBETWEEN(1,ROWS('Top200'!$A$1:$A$200)),1)} -> and
A56: 1 | B56: May | C56: {=INDEX('Top200'!$A$1:$A$200,RANDBETWEEN(1,ROWS('Top200'!$A$1:$A$200)),1)} -> hear | D56: {=INDEX('Top200'!$A$1:$A$200,RANDBETWEEN(1,ROWS('Top200'!$A$1:$A$200)),1)} -> right
A57: 1 | B57: May | C57: {=INDEX('Top200'!$A$1:$A$200,RANDBETWEEN(1,ROWS('Top200'!$A$1:$A$200)),1)} -> this | D57: {=INDEX('Top200'!$A$1:$A$200,RANDBETWEEN(1,ROWS('Top200'!$A$1:$A$200)),1)} -> try
...

Sheet PersonPair_Snap1
A1: * Note only top 200 words | Q1: PersonID
A2: PersonID | B2: Atom1 | C2: Atom2 | E2: PersonID | F2: Atom1 | G2: Atom2 | I2: PersonID | J2: Atom1 | K2: Atom2 | M2: PersonID | N2: Atom1 | O2: Atom2 | Q2: Num | R2: Atom1 | S2: Atom2
A3: 1 | B3: who | C3: feel | E3: 2 | F3: say | G3: study | I3: 3 | J3: always | K3: between | M3: 4 | N3: not | O3: question | Q3: 5 | R3: many | S3: number
A4: 1 | B4: seem | C4: week | E4: 2 | F4: some | G4: woman | I4: 3 | J4: country | K4: each | M4: 4 | N4: she | O4: different | Q4: 5 | R4: bring | S4: also
A5: 1 | B5: help | C5: most | E5: 2 | F5: during | G5: never | I5: 3 | J5: book | K5: even | M5: 4 | N5: come | O5: few | Q5: 5 | R5: each | S5: from
A6: 1 | B6: million | C6: way | E6: 2 | F6: over | G6: good | I6: 3 | J6: high | K6: the | M6: 4 | N6: new | O6: keep | Q6: 5 | R6: next | S6: work
A7: 1 | B7: must | C7: ask | E7: 2 | F7: life | G7: work | I7: 3 | J7: system | K7: not | M7: 4 | N7: live | O7: much | Q7: 5 | R7: through | S7: become
A8: 1 | B8: give | C8: use | E8: 2 | F8: money | G8: child | I8: 3 | J8: time | K8: old | M8: 4 | N8: she | O8: why | Q8: 5 | R8: off | S8: down
A9: 1 | B9: as | C9: study | E9: 2 | F9: must | G9: tell | I9: 3 | J9: really | K9: million | M9: 4 | N9: out | O9: each | Q9: 5 | R9: right | S9: with
A10: 1 | B10: most | C10: the | E10: 2 | F10: hear | G10: those | I10: 3 | J10: this | K10: job | M10: 4 | N10: well | O10: know | Q10: 5 | R10: run | S10: right
A11: 1 | B11: part | C11: all | E11: 2 | F11: for | G11: say | I11: 3 | J11: you | K11: man | M11: 4 | N11: people | O11: people | Q11: 5 | R11: them | S11: same
A12: 1 | B12: much | C12: let | E12: 2 | F12: call | G12: school | I12: 3 | J12: man | K12: time | M12: 4 | N12: more | O12: with | Q12: 5 | R12: would | S12: must
A13: 1 | B13: some | C13: few | E13: 2 | F13: there | G13: when | I13: 3 | J13: seem | K13: his | M13: 4 | N13: help | O13: same | Q13: 5 | R13: want | S13: under
A14: 1 | B14: back | C14: book | E14: 2 | F14: system | G14: mean | I14: 3 | J14: many | K14: fact | M14: 4 | N14: tell | O14: same | Q14: 5 | R14: hold | S14: problem
... A32: 1 | B32: why | C32: like | E32: 2 | F32: call | G32: government | I32: 3 | J32: most | K32: happen | M32: 4 | N32: feel | O32: American | Q32: 5 | R32: help | S32: see
A33: 1 | B33: over | C33: question | E33: 2 | F33: find | G33: eye | M33: 4 | N33: many | O33: their | Q33: 5 | R33: before | S33: after
A34: 1 | B34: put | C34: very | E34: 2 | F34: thing | G34: job | M34: 4 | N34: ask | O34: government | Q34: 5 | R34: just | S34: man
A35: 1 | B35: may | C35: while | E35: 2 | F35: its | G35: high | M35: 4 | N35: with | O35: never | Q35: 5 | R35: move | S35: come
A36: 1 | B36: company | C36: always | E36: 2 | F36: most | G36: back | M36: 4 | N36: show | O36: then | Q36: 5 | R36: get | S36: small
A37: 1 | B37: something | C37: other | E37: 2 | F37: keep | G37: might | M37: 4 | N37: its | O37: again | Q37: 5 | R37: this | S37: many
A38: 1 | B38: last | C38: few | E38: 2 | F38: can | G38: two | M38: 4 | N38: become | O38: some | Q38: 5 | R38: leave | S38: over
A39: 1 | B39: these | C39: believe | E39: 2 | F39: there | G39: this | M39: 4 | N39: any | O39: over | Q39: 5 | R39: think | S39: find
A40: 1 | B40: find | C40: use | E40: 2 | F40: would | G40: should | M40: 4 | N40: know | O40: under | Q40: 5 | R40: different | S40: her
A41: 1 | B41: want | C41: those | E41: 2 | F41: what | G41: country | M41: 4 | N41: child | O41: think | Q41: 5 | R41: turn | S41: month
A42: 1 | B42: here | C42: American | E42: 2 | F42: well | G42: good | Q42: 5 | R42: study | S42: talk
A43: 1 | B43: money | C43: leave | E43: 2 | F43: good | G43: under
A44: 1 | B44: new | C44: another | E44: 2 | F44: between | G44: who
A45: 1 | B45: during | C45: find | E45: 2 | F45: seem | G45: look
A46: 1 | B46: day | C46: will | E46: 2 | F46: area | G46: time
A47: 1 | B47: woman | C47: between | E47: 2 | F47: government | G47: government
A48: 1 | B48: hear | C48: one | E48: 2 | F48: will | G48: while
A49: 1 | B49: work | C49: him | E49: 2 | F49: young | G49: might
A50: 1 | B50: room | C50: after | E50: 2 | F50: story | G50: day
A51: 1 | B51: must | C51: into | E51: 2 | F51: his | G51: any
A52: 1 | B52: believe | C52: not
A53: 1 | B53: what | C53: and
A54: 1 | B54: with | C54: back
A55: 1 | B55: big | C55: them
A56: 1 | B56: many | C56: this
A57: 1 | B57: there | C57: put
...

Sheet Top200
A1: the
A2: and
A3: have
A4: that
A5: for
A6: you
A7: with
A8: say
A9: this
A10: they
A11: but
A12: his
... A200: job
